Workbook

Sheet 表紙
B3: システム開発受託チーム
B4: 〒100-0001 東京都千代田区千代田1-1
B5: 03-1234-5678
D11: 御見積書
B14: 法人向け契約・請求・入金管理システム
D16: 46184
B20: バージョン | C20: 日付 | D20: 作成者 | E20: 変更内容
B21: 1 | C21: 46184 | D21: 開発元 | E21: 新規作成

Sheet Copy of 前提条件
B2: 見積前提条件
B4: 【1.見積根拠】
B5: ・ここに示す見積もり前提から異なる場合、別途、お見積もりが必要となります。ご了承ください。
B6: ・本見積もりは下記参考資料を基に作成しております。
C7: No. | D7: 名称 | G7: 内容 | L7: 入手時期
C8: 1 | D8: 20231013依頼案.pdf | G8: 案件の概要資料 | L8: 45212
B11: 【2.作業範囲】
B12: ・本見積もりは下記範囲の作業を対応します。
C13: 1.要件定義からいただいた内容を理解の上、Q&Aで要件を確認・分析します。
C14: 2.詳細設計を作成します。
C15: 3.各機能の製造を行います。
C16: 4.単体テスト、および結合テストの項目書を作成し、テストを実施し、不具合を修正します。
C17: 5.本番環境の構築と展開を行います。
C18: 6.受入試験は、検収をいただき、弊社が不具合を修正いたします。
C19: 7.Q&Aはファイルで管理し、1営業日以内にご回答いただく希望です。
B21: 【3.開発実現方法】
B22: ・下記の技術を使用して開発することをご提案します。
C23: No. | D23: カテゴリ | G23: 開発言語・フレームワーク等 | J23: 備考
C24: 1 | D24: バックエンド | G24: Ruby on Rails Neo4j Graph Database
C25: 2 | D25: フロントエンド | G25: d3js, ReactJS
C26: 3 | D26: Serverの情報（デプロイ用） | G26: AWS | J26: アカウントはお客様にご準備いただきます。
B28: ※Neo4J & 3D js & Ruby on Railsの 組み合わせのデモ
C29: https://my-neo4j-movies-app.herokuapp.com/
B31: ※システムフロー
B68: ※Neo4jについて
C69: Neo4jはオープンソー NoSQL型グラフデータベースです。
C70: Neo4jには各種エディションがあり、
C71: 個人の趣味や小規模ビジネスで利用できる無償のコミュニティ・エディションと
C72: ミッションクリティカルな業務に対応し得るエンタープライズ・エディションがあります。
C74: ・グラフデータベースのメリット
D76: リレーショナルデータベース | H76: グラフデータベース
C77: 直感性 | D77: 直感的でない Keyでテーブルを結合するという間接的な作業が必要 | H77: 視覚的・直感的な操作ができる メンテの効率化 → コスト削減
C78: コード量 | D78: 直感的でない Keyでテーブルを結合するという間接的な作業が必要 | H78: 直感的な検索で、記述が少ない 開発コスト・開発時間の大幅削減
C79: 検索速度 | D79: 遅い テーブルの結合がボトルネック | H79: 局所的に検索できるので、速い バッチをリアルタイム化 → ロジックの単純化
C81: ・Neo4jのエディション比較表
C83: エディション | H83: エンタープライズ版 | K83: コミュニティ版
C84: プロパティ・グラフ・モデル | H84: 〇 | K84: 〇
C85: ネイティブ・グラフプロセシング＆ストレージ | H85: 〇 | K85: 〇
C86: ACID準拠（トランザクションの信頼性保証） | H86: 〇 | K86: 〇
C87: Cypher Query言語 | H87: 〇 | K87: 〇
...

Sheet 前提条件
B2: 見積前提条件
B4: 【1.見積根拠】
B5: ・ここに示す見積もり前提から異なる場合、別途、お見積もりが必要となります。ご了承ください。
B6: ・本見積もりは下記参考資料を基に作成しております。
C8: No. | D8: 名称 | G8: 内容 | K8: 入手時期
C9: 1 | D9: お客様要件仕様書・要求事項 | K9: 46175
C10: 2
B12: 【2.作業範囲】
B22: 【3.開発実現方法】
C25: No. | D25: 項目 | G25: 実施方式・対応方針 | J25: 備考
C26: 1
C27: 2
C28: 3
C29: 4
C30: 5
C31: 6
B34: 【4.テスト】
C37: No. | D37: テスト項目 | G37: 確認内容 | J37: 備考
C38: 1
C39: 2
C40: 3
C41: 4
C42: 5
C43: ※複数環境での検証や上記スコープ外のテストケース追加が必要な場合は、別途テスト工数を精算・再見積りいたします。
B45: 【5.マスタスケジュール（案）】
C46: ...
E48: 46235 | G48: 46266 | I48: 46296 | K48: 46327
E49: 第1+第2 | F49: 第3+第4 | G49: 第1+第2 | H49: 第3+第4 | I49: 第1+第2 | J49: 第3+第4 | K49: 第1+第2 | L49: 第3+第4
D50: 事前準備
D51: 基盤構築
D52: 設定・調査
D53: テスト
D54: 受入テスト
C55: ※スケジュールについてのご要望（対応期間など）があれば、ご相談ください。
J56: 開発元の対応
J57: UserSide様がテスト実施、開発元が指摘より対応
B59: 【6.体制構成図（案）】
B85: 【7.納品物】
B86: 本スコープにおける納品成果物（ドキュメントおよび設定一式）は以下の通りです。
C87: ■納品成果物一覧
...

Sheet 見積書
B2: システム開発受託チーム
B3: 〒100-0001 東京都千代田区千代田1-1
B4: 03-1234-5678
B9: 御見積書
B11: =表紙!B14 -> 法人向け契約・請求・入金管理システム
B13: 工数見積
B14: No | C14: 項目 | E14: 単価（円） | F14: 工数 | G14: 単位
B15: 1 | C15: =見積明細書!F99 -> 開発 | E15: 380000 | F15: =見積明細書!H99 -> 6.64 | G15: 人月
B16: 2 | C16: =見積明細書!F100 -> 基本設計 | E16: 380000 | F16: =見積明細書!H100 -> 0 | G16: 人月
B17: 3 | C17: =見積明細書!F101 -> 手順書作成 | E17: 380000 | F17: =見積明細書!H101 -> 0.25 | G17: 人月
B18: 4 | C18: =見積明細書!F102 -> 結合テスト | E18: 380000 | F18: =見積明細書!H102 -> 0.34 | G18: 人月
B19: 5 | C19: =見積明細書!F103 -> BrSE担当 | E19: 400000 | F19: =見積明細書!H103 -> 0.72 | G19: 人月
B20: 6 | C20: =見積明細書!F104 -> プロジェクト管理 | E20: 400000 | F20: =見積明細書!H104 -> 0.72 | G20: 人月
C21: 総合計 | F21: =SUM(F15:F20) -> 8.67 | G21: 人月
B23: コスト
B24: No | C24: 項目 | F24: 金額 | G24: 単位
B25: 1 | C25: 小計（工数×単価）（税別） | F25: =SUMPRODUCT(E15:E20,F15:F20) -> 3323400 | G25: 円
B26: 2 | C26: 税金（10%） | F26: =(F25)*10% -> 332340 | G26: 円
C27: コスト（税込） | F27: =SUM(F25+F26) -> 3655740 | G27: 円

Sheet 見積明細書
A2: システム開発受託チーム
A3: 〒100-0001 東京都千代田区千代田1-1
A4: 03-1234-5678
A8: 御見積詳細書
A9: =表紙!B14 -> 法人向け契約・請求・入金管理システム
A11: 開発
A12: No | B12: カテゴリ | C12: 機能 | D12: 機能詳細 | E12: 開発 | F12: 単体テスト | G12: コードレビュー | H12: 小計 (人時)
A13: 1 | B13: Foundation | C13: Project setup | D13: プロジェクト初期化・階層アーキテクチャ設計・ビルド構成 | E13: 21 | F13: =CEILING((E13)*0.4, 0.1) -> 8.4 | G13: =CEILING((E13)*0.1, 0.1) -> 2.1 | H13: =SUM(E13:G13) -> 31.5
A14: 2 | B14: Foundation | C14: Splash | D14: スプラッシュ画面実装（企業ロゴ・バージョン表示） | E14: 3.5 | F14: =CEILING((E14)*0.4, 0.1) -> 1.4 | G14: =CEILING((E14)*0.1, 0.1) -> 0.4 | H14: =SUM(E14:G14) -> 5.3
A15: 3 | B15: Foundation | C15: Start screen | D15: モード選択画面・ナビゲーション実装 | E15: 7 | F15: =CEILING((E15)*0.4, 0.1) -> 2.8 | G15: =CEILING((E15)*0.1, 0.1) -> 0.7 | H15: =SUM(E15:G15) -> 10.5
A16: 4 | B16: Foundation | C16: Permission | D16: 権限リクエストダイアログ（位置情報/BLE/通知）実装 | E16: 21 | F16: =CEILING((E16)*0.4, 0.1) -> 8.4 | G16: =CEILING((E16)*0.1, 0.1) -> 2.1 | H16: =SUM(E16:G16) -> 31.5
A17: 5 | B17: Foundation | C17: Common UI | D17: 共通UIテーマ・トースト・ダイアログコンポーネント実装 | E17: 21 | F17: =CEILING((E17)*0.4, 0.1) -> 8.4 | G17: =CEILING((E17)*0.1, 0.1) -> 2.1 | H17: =SUM(E17:G17) -> 31.5
A18: 6 | B18: BLE Transport | C18: Central manager | D18: Bluetooth Centralマネージャー初期化・状態管理 | E18: 14 | F18: =CEILING((E18)*0.4, 0.1) -> 5.6 | G18: =CEILING((E18)*0.1, 0.1) -> 1.4 | H18: =SUM(E18:G18) -> 21
A19: 7 | B19: BLE Transport | C19: Scan & list | D19: デバイススキャン・フィルタリング・デバイス一覧表示 | E19: 14 | F19: =CEILING((E19)*0.4, 0.1) -> 5.6 | G19: =CEILING((E19)*0.1, 0.1) -> 1.4 | H19: =SUM(E19:G19) -> 21
A20: 8 | B20: BLE Transport | C20: Connect | D20: 接続・切断・タイムアウト制御・エラーメッセージ表示 | E20: 17.5 | F20: =CEILING((E20)*0.4, 0.1) -> 7 | G20: =CEILING((E20)*0.1, 0.1) -> 1.8 | H20: =SUM(E20:G20) -> 26.3
A21: 9 | B21: BLE Transport | C21: Auto reconnect | D21: 登録済みデバイス自動再接続ロジック実装 | E21: 17.5 | F21: =CEILING((E21)*0.4, 0.1) -> 7 | G21: =CEILING((E21)*0.1, 0.1) -> 1.8 | H21: =SUM(E21:G21) -> 26.3
A22: 10 | B22: BLE Transport | C22: RSSI | D22: RSSIシグナル監視・電波強度ステータスカラー反映 | E22: 10.5 | F22: =CEILING((E22)*0.4, 0.1) -> 4.2 | G22: =CEILING((E22)*0.1, 0.1) -> 1.1 | H22: =SUM(E22:G22) -> 15.8
A23: 11 | B23: BLE Transport | C23: GATT framing | D23: GATTデータ送受信・パケットチャンキング処理 | E23: 21 | F23: =CEILING((E23)*0.4, 0.1) -> 8.4 | G23: =CEILING((E23)*0.1, 0.1) -> 2.1 | H23: =SUM(E23:G23) -> 31.5
A24: 12 | B24: BLE Transport | C24: Background BLE | D24: バックグラウンドモード・状態復元処理 | E24: 28 | F24: =CEILING((E24)*0.4, 0.1) -> 11.2 | G24: =CEILING((E24)*0.1, 0.1) -> 2.8 | H24: =SUM(E24:G24) -> 42
... A50: 38 | B50: Storage & Notification | C50: Notification | D50: ローカルプッシュ通知・フォアグラウンドインジケーター | E50: 14 | F50: =CEILING((E50)*0.4, 0.1) -> 5.6 | G50: =CEILING((E50)*0.1, 0.1) -> 1.4 | H50: =SUM(E50:G50) -> 21
B65: 小計 | E65: =SUM(E13:E50) -> 619.5 | F65: =SUM(F13:F50) -> 247.8 | G65: =SUM(G13:G50) -> 62.8 | H65: =SUM(H13:H50) -> 930.1
A67: 基本設計
A68: 項番 | B68: カテゴリ | C68: 作業内容 | D68: コメント | E68: 工数 | H68: 小計 (人時)
A69: 1 | F69: - | G69: =CEILING((E69)*0.1, 0.1) -> 0 | H69: =SUM(E69:G69) -> 0
A70: 2 | F70: - | G70: =CEILING((E70)*0.1, 0.1) -> 0 | H70: =SUM(E70:G70) -> 0
A71: 3 | F71: - | G71: =CEILING((E71)*0.1, 0.1) -> 0 | H71: =SUM(E71:G71) -> 0
A72: 4 | F72: - | G72: =CEILING((E72)*0.1, 0.1) -> 0 | H72: =SUM(E72:G72) -> 0
B73: 小計 | E73: =SUM(E69:E72) -> 0 | G73: =SUM(G69:G72) -> 0 | H73: =SUM(H69:H72) -> 0
A75: 手順書作成
A76: 項番 | B76: カテゴリ | C76: 作業内容 | D76: コメント | E76: 工数 | H76: 小計 (人時)
A77: 1 | B77: 完成図書 | C77: 納品ドキュメント作成（システム構成図、各種パラメータ設定書、試験結果報告書） | D77: 日本語、標準詳細度 | E77: 16 | F77: - | G77: =CEILING((E77)*0.1, 0.1) -> 1.6 | H77: =SUM(E77:G77) -> 17.6
A78: 2 | B78: Handover | C78: 運用引継ぎおよび各種設計・手順ドキュメントの説明・質疑応答 | E78: 16 | F78: - | G78: =CEILING((E78)*0.1, 0.1) -> 1.6 | H78: =SUM(E78:G78) -> 17.6
B79: 小計 | E79: =SUM(E77:E78) -> 32 | G79: =SUM(G77:G78) -> 3.2 | H79: =SUM(H77:H78) -> 35.2
A81: 結合テスト
A82: 項番 | B82: カテゴリ | C82: 作業内容 | D82: コメント | E82: 工数 | H82: 小計 (人時)
A83: 1 | B83: Test design | C83: テスト計画書・テストケース作成（単体テスト・結合テスト仕様） | E83: 8 | F83: - | G83: - | H83: =SUM(E83:G83) -> 8
A84: 3 | B84: Integration test | C84: エンドツーエンド結合テストシナリオ検証・不具合修正 | D84: テスト検証環境提供前提 | E84: 40 | F84: - | G84: - | H84: =SUM(E84:G84) -> 40
B85: 小計 | E85: =SUM(E83:E84) -> 48 | G85: =SUM(G83:G84) -> 0 | H85: =SUM(H83:H84) -> 48
A87: BrSE担当
A88: 項番 | B88: カテゴリ | C88: 作業内容 | D88: コメント | E88: 工数 | H88: 小計 (人時)
...
